{
 "cells": [
  {
   "cell_type": "code",
   "execution_count": 34,
   "metadata": {},
   "outputs": [
    {
     "name": "stdout",
     "output_type": "stream",
     "text": [
      "Using GPU is CUDA:0\n"
     ]
    }
   ],
   "source": [
    "import os    \n",
    "import tensorflow as tf\n",
    "import tensorflow_datasets as tfds\n",
    "import numpy as np\n",
    "\n",
    "os.environ[\"CUDA_DEVICE_ORDER\"] = \"PCI_BUS_ID\"\n",
    "os.environ[\"CUDA_VISIBLE_DEVICES\"] = \"0\"\n",
    "print(f\"Using GPU is CUDA:{os.environ['CUDA_VISIBLE_DEVICES']}\")\n",
    "#used https://www.tensorflow.org/datasets/keras_example for my project, was a huge help\n",
    "#for understanding what I needed to do\n",
    "#https://stackoverflow.com/questions/64645503/tensorflow-datasets-cannot-batch-tensors-of-different-shapes-error-even-after-r\n",
    "#\n",
    "\n",
    "\n",
    "#grabs all my gpus (1) for helping to limit the memory growth\n",
    "#using the GPU will make the training faster and prevent out of memory errors"
   ]
  },
  {
   "cell_type": "code",
   "execution_count": 39,
   "metadata": {},
   "outputs": [],
   "source": [
    "#training pipeline\n",
    "#creating a function that will normalize the pictures into the correct types\n",
    "def normal_image(image, label):\n",
    "   image = tf.image.resize(image, [180,180])\n",
    "   return tf.cast(image, tf.float32) / 255., label\n"
   ]
  },
  {
   "cell_type": "code",
   "execution_count": 47,
   "metadata": {},
   "outputs": [],
   "source": [
    "#initializing the testing and training datasets with parameters \n",
    "(ds_train, ds_test) = tfds.load(\n",
    "    name ='stanford_dogs',\n",
    "    split=['train', 'test'],\n",
    "    as_supervised=True,\n",
    "\n",
    ")\n",
    "\n",
    "#mapping the training data for correct type\n",
    "ds_train = ds_train.shuffle(1024)\n",
    "ds_train = ds_train.map(normal_image, num_parallel_calls=tf.data.AUTOTUNE)\n",
    "\n",
    "ds_train = ds_train.batch(32)\n"
   ]
  },
  {
   "cell_type": "code",
   "execution_count": 48,
   "metadata": {},
   "outputs": [],
   "source": [
    "#building an evaluation pipeline\n",
    "#testing pipeline\n",
    "ds_test = ds_test.map(\n",
    "    normal_image, num_parallel_calls=tf.data.AUTOTUNE)\n",
    "ds_test = ds_test.batch(128)\n",
    "#you cache after batching because you oculd have the same batch between epochs\n",
    "ds_test = ds_test.cache()\n",
    "ds_test = ds_test.prefetch(tf.data.AUTOTUNE)"
   ]
  },
  {
   "cell_type": "code",
   "execution_count": 49,
   "metadata": {},
   "outputs": [
    {
     "name": "stdout",
     "output_type": "stream",
     "text": [
      "Epoch 1/6\n"
     ]
    },
    {
     "ename": "ValueError",
     "evalue": "in user code:\n\n    File \"c:\\Users\\drewp\\AppData\\Local\\Programs\\Python\\Python311\\Lib\\site-packages\\keras\\engine\\training.py\", line 1284, in train_function  *\n        return step_function(self, iterator)\n    File \"c:\\Users\\drewp\\AppData\\Local\\Programs\\Python\\Python311\\Lib\\site-packages\\keras\\engine\\training.py\", line 1268, in step_function  **\n        outputs = model.distribute_strategy.run(run_step, args=(data,))\n    File \"c:\\Users\\drewp\\AppData\\Local\\Programs\\Python\\Python311\\Lib\\site-packages\\keras\\engine\\training.py\", line 1249, in run_step  **\n        outputs = model.train_step(data)\n    File \"c:\\Users\\drewp\\AppData\\Local\\Programs\\Python\\Python311\\Lib\\site-packages\\keras\\engine\\training.py\", line 1050, in train_step\n        y_pred = self(x, training=True)\n    File \"c:\\Users\\drewp\\AppData\\Local\\Programs\\Python\\Python311\\Lib\\site-packages\\keras\\utils\\traceback_utils.py\", line 70, in error_handler\n        raise e.with_traceback(filtered_tb) from None\n    File \"c:\\Users\\drewp\\AppData\\Local\\Programs\\Python\\Python311\\Lib\\site-packages\\keras\\engine\\input_spec.py\", line 280, in assert_input_compatibility\n        raise ValueError(\n\n    ValueError: Exception encountered when calling layer 'sequential_13' (type Sequential).\n    \n    Input 0 of layer \"dense_21\" is incompatible with the layer: expected axis -1 of input shape to have value 32400, but received input with shape (None, 97200)\n    \n    Call arguments received by layer 'sequential_13' (type Sequential):\n      • inputs=tf.Tensor(shape=(None, 180, 180, 3), dtype=float32)\n      • training=True\n      • mask=None\n",
     "output_type": "error",
     "traceback": [
      "\u001b[1;31m---------------------------------------------------------------------------\u001b[0m",
      "\u001b[1;31mValueError\u001b[0m                                Traceback (most recent call last)",
      "Cell \u001b[1;32mIn[49], line 12\u001b[0m\n\u001b[0;32m      1\u001b[0m model \u001b[39m=\u001b[39m tf\u001b[39m.\u001b[39mkeras\u001b[39m.\u001b[39mmodels\u001b[39m.\u001b[39mSequential([\n\u001b[0;32m      2\u001b[0m   tf\u001b[39m.\u001b[39mkeras\u001b[39m.\u001b[39mlayers\u001b[39m.\u001b[39mFlatten(input_shape\u001b[39m=\u001b[39m(\u001b[39m180\u001b[39m, \u001b[39m180\u001b[39m)),\n\u001b[0;32m      3\u001b[0m   tf\u001b[39m.\u001b[39mkeras\u001b[39m.\u001b[39mlayers\u001b[39m.\u001b[39mDense(\u001b[39m128\u001b[39m, activation\u001b[39m=\u001b[39m\u001b[39m'\u001b[39m\u001b[39mrelu\u001b[39m\u001b[39m'\u001b[39m),\n\u001b[0;32m      4\u001b[0m   tf\u001b[39m.\u001b[39mkeras\u001b[39m.\u001b[39mlayers\u001b[39m.\u001b[39mDense(\u001b[39m10\u001b[39m)\n\u001b[0;32m      5\u001b[0m ])\n\u001b[0;32m      6\u001b[0m model\u001b[39m.\u001b[39mcompile(\n\u001b[0;32m      7\u001b[0m     optimizer\u001b[39m=\u001b[39mtf\u001b[39m.\u001b[39mkeras\u001b[39m.\u001b[39moptimizers\u001b[39m.\u001b[39mAdam(\u001b[39m0.001\u001b[39m),\n\u001b[0;32m      8\u001b[0m     loss\u001b[39m=\u001b[39mtf\u001b[39m.\u001b[39mkeras\u001b[39m.\u001b[39mlosses\u001b[39m.\u001b[39mSparseCategoricalCrossentropy(from_logits\u001b[39m=\u001b[39m\u001b[39mTrue\u001b[39;00m),\n\u001b[0;32m      9\u001b[0m     metrics\u001b[39m=\u001b[39m[tf\u001b[39m.\u001b[39mkeras\u001b[39m.\u001b[39mmetrics\u001b[39m.\u001b[39mSparseCategoricalAccuracy()],\n\u001b[0;32m     10\u001b[0m )\n\u001b[1;32m---> 12\u001b[0m model\u001b[39m.\u001b[39;49mfit(\n\u001b[0;32m     13\u001b[0m     ds_train,\n\u001b[0;32m     14\u001b[0m     epochs\u001b[39m=\u001b[39;49m\u001b[39m6\u001b[39;49m,\n\u001b[0;32m     15\u001b[0m     validation_data\u001b[39m=\u001b[39;49mds_test\n\u001b[0;32m     16\u001b[0m )\n",
      "File \u001b[1;32mc:\\Users\\drewp\\AppData\\Local\\Programs\\Python\\Python311\\Lib\\site-packages\\keras\\utils\\traceback_utils.py:70\u001b[0m, in \u001b[0;36mfilter_traceback.<locals>.error_handler\u001b[1;34m(*args, **kwargs)\u001b[0m\n\u001b[0;32m     67\u001b[0m     filtered_tb \u001b[39m=\u001b[39m _process_traceback_frames(e\u001b[39m.\u001b[39m__traceback__)\n\u001b[0;32m     68\u001b[0m     \u001b[39m# To get the full stack trace, call:\u001b[39;00m\n\u001b[0;32m     69\u001b[0m     \u001b[39m# `tf.debugging.disable_traceback_filtering()`\u001b[39;00m\n\u001b[1;32m---> 70\u001b[0m     \u001b[39mraise\u001b[39;00m e\u001b[39m.\u001b[39mwith_traceback(filtered_tb) \u001b[39mfrom\u001b[39;00m \u001b[39mNone\u001b[39;00m\n\u001b[0;32m     71\u001b[0m \u001b[39mfinally\u001b[39;00m:\n\u001b[0;32m     72\u001b[0m     \u001b[39mdel\u001b[39;00m filtered_tb\n",
      "File \u001b[1;32m~\\AppData\\Local\\Temp\\__autograph_generated_filex07d5cbh.py:15\u001b[0m, in \u001b[0;36mouter_factory.<locals>.inner_factory.<locals>.tf__train_function\u001b[1;34m(iterator)\u001b[0m\n\u001b[0;32m     13\u001b[0m \u001b[39mtry\u001b[39;00m:\n\u001b[0;32m     14\u001b[0m     do_return \u001b[39m=\u001b[39m \u001b[39mTrue\u001b[39;00m\n\u001b[1;32m---> 15\u001b[0m     retval_ \u001b[39m=\u001b[39m ag__\u001b[39m.\u001b[39mconverted_call(ag__\u001b[39m.\u001b[39mld(step_function), (ag__\u001b[39m.\u001b[39mld(\u001b[39mself\u001b[39m), ag__\u001b[39m.\u001b[39mld(iterator)), \u001b[39mNone\u001b[39;00m, fscope)\n\u001b[0;32m     16\u001b[0m \u001b[39mexcept\u001b[39;00m:\n\u001b[0;32m     17\u001b[0m     do_return \u001b[39m=\u001b[39m \u001b[39mFalse\u001b[39;00m\n",
      "\u001b[1;31mValueError\u001b[0m: in user code:\n\n    File \"c:\\Users\\drewp\\AppData\\Local\\Programs\\Python\\Python311\\Lib\\site-packages\\keras\\engine\\training.py\", line 1284, in train_function  *\n        return step_function(self, iterator)\n    File \"c:\\Users\\drewp\\AppData\\Local\\Programs\\Python\\Python311\\Lib\\site-packages\\keras\\engine\\training.py\", line 1268, in step_function  **\n        outputs = model.distribute_strategy.run(run_step, args=(data,))\n    File \"c:\\Users\\drewp\\AppData\\Local\\Programs\\Python\\Python311\\Lib\\site-packages\\keras\\engine\\training.py\", line 1249, in run_step  **\n        outputs = model.train_step(data)\n    File \"c:\\Users\\drewp\\AppData\\Local\\Programs\\Python\\Python311\\Lib\\site-packages\\keras\\engine\\training.py\", line 1050, in train_step\n        y_pred = self(x, training=True)\n    File \"c:\\Users\\drewp\\AppData\\Local\\Programs\\Python\\Python311\\Lib\\site-packages\\keras\\utils\\traceback_utils.py\", line 70, in error_handler\n        raise e.with_traceback(filtered_tb) from None\n    File \"c:\\Users\\drewp\\AppData\\Local\\Programs\\Python\\Python311\\Lib\\site-packages\\keras\\engine\\input_spec.py\", line 280, in assert_input_compatibility\n        raise ValueError(\n\n    ValueError: Exception encountered when calling layer 'sequential_13' (type Sequential).\n    \n    Input 0 of layer \"dense_21\" is incompatible with the layer: expected axis -1 of input shape to have value 32400, but received input with shape (None, 97200)\n    \n    Call arguments received by layer 'sequential_13' (type Sequential):\n      • inputs=tf.Tensor(shape=(None, 180, 180, 3), dtype=float32)\n      • training=True\n      • mask=None\n"
     ]
    }
   ],
   "source": [
    "model = tf.keras.models.Sequential([\n",
    "  tf.keras.layers.Flatten(input_shape=(180, 180)),\n",
    "  tf.keras.layers.Dense(128, activation='relu'),\n",
    "  tf.keras.layers.Dense(10)\n",
    "])\n",
    "model.compile(\n",
    "    optimizer=tf.keras.optimizers.Adam(0.001),\n",
    "    loss=tf.keras.losses.SparseCategoricalCrossentropy(from_logits=True),\n",
    "    metrics=[tf.keras.metrics.SparseCategoricalAccuracy()],\n",
    ")\n",
    "\n",
    "model.fit(\n",
    "    ds_train,\n",
    "    epochs=6,\n",
    "    validation_data=ds_test\n",
    ")"
   ]
  }
 ],
 "metadata": {
  "kernelspec": {
   "display_name": "Python 3",
   "language": "python",
   "name": "python3"
  },
  "language_info": {
   "codemirror_mode": {
    "name": "ipython",
    "version": 3
   },
   "file_extension": ".py",
   "mimetype": "text/x-python",
   "name": "python",
   "nbconvert_exporter": "python",
   "pygments_lexer": "ipython3",
   "version": "3.11.3"
  },
  "orig_nbformat": 4
 },
 "nbformat": 4,
 "nbformat_minor": 2
}
